
Exception caught at 2021-11-07 16:31:08.662026:
Traceback (most recent call last):
  File "internal/testpy/test_framework.py", line 238, in <module>
    main()
  File "internal/testpy/test_framework.py", line 41, in main
    input("Press Enter to Exit...")
EOFError
